Not Found: /tomo_statistics/2/users
Internal Server Error: /admin
Traceback (most recent call last):
  File "/Users/matija/.virtualenv/tomo/lib/python3.6/site-packages/django/db/backends/utils.py", line 64, in execute
    return self.cursor.execute(sql, params)
psycopg2.ProgrammingError: relation "silk_request" does not exist
LINE 1: INSERT INTO "silk_request" ("id", "path", "query_params", "r...
                    ^


The above exception was the direct cause of the following exception:

Traceback (most recent call last):
  File "/Users/matija/.virtualenv/tomo/lib/python3.6/site-packages/django/core/handlers/base.py", line 123, in get_response
    response = middleware_method(request)
  File "/Users/matija/.virtualenv/tomo/lib/python3.6/site-packages/silk/middleware.py", line 103, in process_request
    request_model = RequestModelFactory(request).construct_request_model()
  File "/Users/matija/.virtualenv/tomo/lib/python3.6/site-packages/silk/model_factory.py", line 200, in construct_request_model
    body=body)
  File "/Users/matija/.virtualenv/tomo/lib/python3.6/site-packages/django/db/models/manager.py", line 122, in manager_method
    return getattr(self.get_queryset(), name)(*args, **kwargs)
  File "/Users/matija/.virtualenv/tomo/lib/python3.6/site-packages/django/db/models/query.py", line 401, in create
    obj.save(force_insert=True, using=self.db)
  File "/Users/matija/.virtualenv/tomo/lib/python3.6/site-packages/silk/models.py", line 130, in save
    super(Request, self).save(*args, **kwargs)
  File "/Users/matija/.virtualenv/tomo/lib/python3.6/site-packages/django/db/models/base.py", line 708, in save
    force_update=force_update, update_fields=update_fields)
  File "/Users/matija/.virtualenv/tomo/lib/python3.6/site-packages/django/db/models/base.py", line 736, in save_base
    updated = self._save_table(raw, cls, force_insert, force_update, using, update_fields)
  File "/Users/matija/.virtualenv/tomo/lib/python3.6/site-packages/django/db/models/base.py", line 820, in _save_table
    result = self._do_insert(cls._base_manager, using, fields, update_pk, raw)
  File "/Users/matija/.virtualenv/tomo/lib/python3.6/site-packages/django/db/models/base.py", line 859, in _do_insert
    using=using, raw=raw)
  File "/Users/matija/.virtualenv/tomo/lib/python3.6/site-packages/django/db/models/manager.py", line 122, in manager_method
    return getattr(self.get_queryset(), name)(*args, **kwargs)
  File "/Users/matija/.virtualenv/tomo/lib/python3.6/site-packages/django/db/models/query.py", line 1039, in _insert
    return query.get_compiler(using=using).execute_sql(return_id)
  File "/Users/matija/.virtualenv/tomo/lib/python3.6/site-packages/django/db/models/sql/compiler.py", line 1060, in execute_sql
    cursor.execute(sql, params)
  File "/Users/matija/.virtualenv/tomo/lib/python3.6/site-packages/django/db/backends/utils.py", line 79, in execute
    return super(CursorDebugWrapper, self).execute(sql, params)
  File "/Users/matija/.virtualenv/tomo/lib/python3.6/site-packages/django/db/backends/utils.py", line 64, in execute
    return self.cursor.execute(sql, params)
  File "/Users/matija/.virtualenv/tomo/lib/python3.6/site-packages/django/db/utils.py", line 95, in __exit__
    six.reraise(dj_exc_type, dj_exc_value, traceback)
  File "/Users/matija/.virtualenv/tomo/lib/python3.6/site-packages/django/utils/six.py", line 685, in reraise
    raise value.with_traceback(tb)
  File "/Users/matija/.virtualenv/tomo/lib/python3.6/site-packages/django/db/backends/utils.py", line 64, in execute
    return self.cursor.execute(sql, params)
django.db.utils.ProgrammingError: relation "silk_request" does not exist
LINE 1: INSERT INTO "silk_request" ("id", "path", "query_params", "r...
                    ^

Internal Server Error: /favicon.ico
Traceback (most recent call last):
  File "/Users/matija/.virtualenv/tomo/lib/python3.6/site-packages/django/db/backends/utils.py", line 64, in execute
    return self.cursor.execute(sql, params)
psycopg2.ProgrammingError: relation "silk_request" does not exist
LINE 1: INSERT INTO "silk_request" ("id", "path", "query_params", "r...
                    ^


The above exception was the direct cause of the following exception:

Traceback (most recent call last):
  File "/Users/matija/.virtualenv/tomo/lib/python3.6/site-packages/django/core/handlers/base.py", line 123, in get_response
    response = middleware_method(request)
  File "/Users/matija/.virtualenv/tomo/lib/python3.6/site-packages/silk/middleware.py", line 103, in process_request
    request_model = RequestModelFactory(request).construct_request_model()
  File "/Users/matija/.virtualenv/tomo/lib/python3.6/site-packages/silk/model_factory.py", line 200, in construct_request_model
    body=body)
  File "/Users/matija/.virtualenv/tomo/lib/python3.6/site-packages/django/db/models/manager.py", line 122, in manager_method
    return getattr(self.get_queryset(), name)(*args, **kwargs)
  File "/Users/matija/.virtualenv/tomo/lib/python3.6/site-packages/django/db/models/query.py", line 401, in create
    obj.save(force_insert=True, using=self.db)
  File "/Users/matija/.virtualenv/tomo/lib/python3.6/site-packages/silk/models.py", line 130, in save
    super(Request, self).save(*args, **kwargs)
  File "/Users/matija/.virtualenv/tomo/lib/python3.6/site-packages/django/db/models/base.py", line 708, in save
    force_update=force_update, update_fields=update_fields)
  File "/Users/matija/.virtualenv/tomo/lib/python3.6/site-packages/django/db/models/base.py", line 736, in save_base
    updated = self._save_table(raw, cls, force_insert, force_update, using, update_fields)
  File "/Users/matija/.virtualenv/tomo/lib/python3.6/site-packages/django/db/models/base.py", line 820, in _save_table
    result = self._do_insert(cls._base_manager, using, fields, update_pk, raw)
  File "/Users/matija/.virtualenv/tomo/lib/python3.6/site-packages/django/db/models/base.py", line 859, in _do_insert
    using=using, raw=raw)
  File "/Users/matija/.virtualenv/tomo/lib/python3.6/site-packages/django/db/models/manager.py", line 122, in manager_method
    return getattr(self.get_queryset(), name)(*args, **kwargs)
  File "/Users/matija/.virtualenv/tomo/lib/python3.6/site-packages/django/db/models/query.py", line 1039, in _insert
    return query.get_compiler(using=using).execute_sql(return_id)
  File "/Users/matija/.virtualenv/tomo/lib/python3.6/site-packages/django/db/models/sql/compiler.py", line 1060, in execute_sql
    cursor.execute(sql, params)
  File "/Users/matija/.virtualenv/tomo/lib/python3.6/site-packages/django/db/backends/utils.py", line 79, in execute
    return super(CursorDebugWrapper, self).execute(sql, params)
  File "/Users/matija/.virtualenv/tomo/lib/python3.6/site-packages/django/db/backends/utils.py", line 64, in execute
    return self.cursor.execute(sql, params)
  File "/Users/matija/.virtualenv/tomo/lib/python3.6/site-packages/django/db/utils.py", line 95, in __exit__
    six.reraise(dj_exc_type, dj_exc_value, traceback)
  File "/Users/matija/.virtualenv/tomo/lib/python3.6/site-packages/django/utils/six.py", line 685, in reraise
    raise value.with_traceback(tb)
  File "/Users/matija/.virtualenv/tomo/lib/python3.6/site-packages/django/db/backends/utils.py", line 64, in execute
    return self.cursor.execute(sql, params)
django.db.utils.ProgrammingError: relation "silk_request" does not exist
LINE 1: INSERT INTO "silk_request" ("id", "path", "query_params", "r...
                    ^

Not Found: /favicon.ico
Not Found: /favicon.ico
Not Found: /favicon.ico
Not Found: /favicon.ico
Not Found: /favicon.ico
Not Found: /problems/5101/solutions/2574/
Internal Server Error: /admin/attempts/attempt/
Traceback (most recent call last):
  File "/Users/matija/.virtualenv/tomo/lib/python3.6/site-packages/django/core/handlers/base.py", line 149, in get_response
    response = self.process_exception_by_middleware(e, request)
  File "/Users/matija/.virtualenv/tomo/lib/python3.6/site-packages/django/core/handlers/base.py", line 147, in get_response
    response = wrapped_callback(request, *callback_args, **callback_kwargs)
  File "/Users/matija/.virtualenv/tomo/lib/python3.6/site-packages/django/contrib/admin/options.py", line 541, in wrapper
    return self.admin_site.admin_view(view)(*args, **kwargs)
  File "/Users/matija/.virtualenv/tomo/lib/python3.6/site-packages/django/utils/decorators.py", line 149, in _wrapped_view
    response = view_func(request, *args, **kwargs)
  File "/Users/matija/.virtualenv/tomo/lib/python3.6/site-packages/django/views/decorators/cache.py", line 57, in _wrapped_view_func
    response = view_func(request, *args, **kwargs)
  File "/Users/matija/.virtualenv/tomo/lib/python3.6/site-packages/django/contrib/admin/sites.py", line 244, in inner
    return view(request, *args, **kwargs)
  File "/Users/matija/.virtualenv/tomo/lib/python3.6/site-packages/django/utils/decorators.py", line 67, in _wrapper
    return bound_func(*args, **kwargs)
  File "/Users/matija/.virtualenv/tomo/lib/python3.6/site-packages/django/utils/decorators.py", line 149, in _wrapped_view
    response = view_func(request, *args, **kwargs)
  File "/Users/matija/.virtualenv/tomo/lib/python3.6/site-packages/django/utils/decorators.py", line 63, in bound_func
    return func.__get__(self, type(self))(*args2, **kwargs2)
  File "/Users/matija/.virtualenv/tomo/lib/python3.6/site-packages/django/contrib/admin/options.py", line 1470, in changelist_view
    self.list_max_show_all, self.list_editable, self)
  File "/Users/matija/.virtualenv/tomo/lib/python3.6/site-packages/django/contrib/admin/views/main.py", line 78, in __init__
    self.queryset = self.get_queryset(request)
  File "/Users/matija/.virtualenv/tomo/lib/python3.6/site-packages/django/contrib/admin/views/main.py", line 356, in get_queryset
    request, qs, self.query)
  File "/Users/matija/.virtualenv/tomo/lib/python3.6/site-packages/django/contrib/admin/options.py", line 900, in get_search_results
    queryset = queryset.filter(reduce(operator.or_, or_queries))
  File "/Users/matija/.virtualenv/tomo/lib/python3.6/site-packages/django/db/models/query.py", line 790, in filter
    return self._filter_or_exclude(False, *args, **kwargs)
  File "/Users/matija/.virtualenv/tomo/lib/python3.6/site-packages/django/db/models/query.py", line 808, in _filter_or_exclude
    clone.query.add_q(Q(*args, **kwargs))
  File "/Users/matija/.virtualenv/tomo/lib/python3.6/site-packages/django/db/models/sql/query.py", line 1243, in add_q
    clause, _ = self._add_q(q_object, self.used_aliases)
  File "/Users/matija/.virtualenv/tomo/lib/python3.6/site-packages/django/db/models/sql/query.py", line 1263, in _add_q
    current_negated, allow_joins, split_subq)
  File "/Users/matija/.virtualenv/tomo/lib/python3.6/site-packages/django/db/models/sql/query.py", line 1269, in _add_q
    allow_joins=allow_joins, split_subq=split_subq,
  File "/Users/matija/.virtualenv/tomo/lib/python3.6/site-packages/django/db/models/sql/query.py", line 1149, in build_filter
    lookups, parts, reffed_expression = self.solve_lookup_type(arg)
  File "/Users/matija/.virtualenv/tomo/lib/python3.6/site-packages/django/db/models/sql/query.py", line 1035, in solve_lookup_type
    _, field, _, lookup_parts = self.names_to_path(lookup_splitted, self.get_meta())
  File "/Users/matija/.virtualenv/tomo/lib/python3.6/site-packages/django/db/models/sql/query.py", line 1330, in names_to_path
    "Choices are: %s" % (name, ", ".join(available)))
django.core.exceptions.FieldError: Cannot resolve keyword 'problem' into field. Choices are: feedback, id, part, part_id, solution, submission_date, user, user_id, valid
